<?xml version="1.0" encoding="utf-8"?>
<!-- This URDF was automatically created by SolidWorks to URDF Exporter! Originally created by Stephen Brawner (brawner@gmail.com) 
     Commit Version: 1.5.1-0-g916b5db  Build Version: 1.5.7152.31018
     For more information, please see http://wiki.ros.org/sw_urdf_exporter -->
<robot
  name="robot9">
  <link
    name="base_link">
    <inertial>
      <origin
        xyz="0.0098794 -4.1862E-17 0.0034954"
        rpy="0 0 0" />
      <mass
        value="71.854" />
      <inertia
        ixx="1.657"
        ixy="-5.7485E-16"
        ixz="0.021573"
        iyy="5.8166"
        iyz="1.4772E-16"
        izz="7.1645" />
    </inertial>
    <visual>
      <origin
        xyz="0 0 0"
        rpy="0 0 0" />
      <geometry>
        <mesh
          filename="package://robot9/meshes/base_link.STL" />
      </geometry>
      <material
        name="">
        <color
          rgba="0.79216 0.81961 0.93333 1" />
      </material>
    </visual>
    <collision>
      <origin
        xyz="0 0 0"
        rpy="0 0 0" />
      <geometry>
        <mesh
          filename="package://robot9/meshes/base_link.STL" />
      </geometry>
    </collision>
  </link>
  <link
    name="right_wheel_link">
    <inertial>
      <origin
        xyz="0 0 -0.054877"
        rpy="0 0 0" />
      <mass
        value="1.8206" />
      <inertia
        ixx="0.0042591"
        ixy="-5.421E-20"
        ixz="5.3908E-20"
        iyy="0.0042591"
        iyz="6.8415E-21"
        izz="0.00656" />
    </inertial>
    <visual>
      <origin
        xyz="0 0 0"
        rpy="0 0 0" />
      <geometry>
        <mesh
          filename="package://robot9/meshes/right_wheel_link.STL" />
      </geometry>
      <material
        name="">
        <color
          rgba="0.79216 0.81961 0.93333 1" />
      </material>
    </visual>
    <collision>
      <origin
        xyz="0 0 0"
        rpy="0 0 0" />
      <geometry>
        <mesh
          filename="package://robot9/meshes/right_wheel_link.STL" />
      </geometry>
    </collision>
  </link>
  <joint
    name="right_wheel_joint"
    type="continuous">
    <origin
      xyz="0.32 -0.155 -0.064926"
      rpy="-1.5708 0.13359 0" />
    <parent
      link="base_link" />
    <child
      link="right_wheel_link" />
    <axis
      xyz="0 0 1" />
  </joint>
  <link
    name="left_wheel_link">
    <inertial>
      <origin
        xyz="2.7756E-17 0 -0.054877"
        rpy="0 0 0" />
      <mass
        value="1.8206" />
      <inertia
        ixx="0.0042591"
        ixy="-4.3368E-19"
        ixz="1.5916E-19"
        iyy="0.0042591"
        iyz="1.3035E-20"
        izz="0.00656" />
    </inertial>
    <visual>
      <origin
        xyz="0 0 0"
        rpy="0 0 0" />
      <geometry>
        <mesh
          filename="package://robot9/meshes/left_wheel_link.STL" />
      </geometry>
      <material
        name="">
        <color
          rgba="0.79216 0.81961 0.93333 1" />
      </material>
    </visual>
    <collision>
      <origin
        xyz="0 0 0"
        rpy="0 0 0" />
      <geometry>
        <mesh
          filename="package://robot9/meshes/left_wheel_link.STL" />
      </geometry>
    </collision>
  </link>
  <joint
    name="left_wheel_joint"
    type="continuous">
    <origin
      xyz="0.32 0.155 -0.064926"
      rpy="-1.5708 -1.2488 3.1416" />
    <parent
      link="base_link" />
    <child
      link="left_wheel_link" />
    <axis
      xyz="0 0 1" />
  </joint>
  <link
    name="laser_sick_link">
    <inertial>
      <origin
        xyz="2.3225E-09 0.00059635 0.07464"
        rpy="0 0 0" />
      <mass
        value="29.076" />
      <inertia
        ixx="0.13416"
        ixy="2.4047E-09"
        ixz="-5.1043E-09"
        iyy="0.10224"
        iyz="-0.0099819"
        izz="0.13751" />
    </inertial>
    <visual>
      <origin
        xyz="0 0 0"
        rpy="0 0 0" />
      <geometry>
        <mesh
          filename="package://robot9/meshes/laser_sick_link.STL" />
      </geometry>
      <material
        name="">
        <color
          rgba="0.75294 0.75294 0.75294 1" />
      </material>
    </visual>
    <collision>
      <origin
        xyz="0 0 0"
        rpy="0 0 0" />
      <geometry>
        <mesh
          filename="package://robot9/meshes/laser_sick_link.STL" />
      </geometry>
    </collision>
  </link>
  <joint
    name="laser_sick_joint"
    type="fixed">
    <origin
      xyz="0.501 0 0.0125"
      rpy="1.5708 0 1.5708" />
    <parent
      link="base_link" />
    <child
      link="laser_sick_link" />
    <axis
      xyz="0 0 0" />
  </joint>
  <link
    name="fork_c_joint">
    <inertial>
      <origin
        xyz="0 0 0"
        rpy="0 0 0" />
      <mass
        value="0" />
      <inertia
        ixx="0"
        ixy="0"
        ixz="0"
        iyy="0"
        iyz="0"
        izz="0" />
    </inertial>
    <visual>
      <origin
        xyz="0 0 0"
        rpy="0 0 0" />
      <geometry>
        <mesh
          filename="package://robot9/meshes/fork_c_joint.STL" />
      </geometry>
      <material
        name="">
        <color
          rgba="1 1 1 1" />
      </material>
    </visual>
    <collision>
      <origin
        xyz="0 0 0"
        rpy="0 0 0" />
      <geometry>
        <mesh
          filename="package://robot9/meshes/fork_c_joint.STL" />
      </geometry>
    </collision>
  </link>
  <joint
    name="fork_c_joint"
    type="continuous">
    <origin
      xyz="-0.36 0 0"
      rpy="1.5708 0 -2.6139" />
    <parent
      link="base_link" />
    <child
      link="fork_c_joint" />
    <axis
      xyz="0 1 0" />
  </joint>
  <link
    name="wheel_c_link">
    <inertial>
      <origin
        xyz="1.6653E-16 4.1633E-17 1.9151E-15"
        rpy="0 0 0" />
      <mass
        value="0.56957" />
      <inertia
        ixx="0.00097832"
        ixy="-7.3059E-21"
        ixz="-4.8789E-19"
        iyy="0.00097832"
        iyz="-2.9758E-18"
        izz="0.0017885" />
    </inertial>
    <visual>
      <origin
        xyz="0 0 0"
        rpy="0 0 0" />
      <geometry>
        <mesh
          filename="package://robot9/meshes/wheel_c_link.STL" />
      </geometry>
      <material
        name="">
        <color
          rgba="1 1 1 1" />
      </material>
    </visual>
    <collision>
      <origin
        xyz="0 0 0"
        rpy="0 0 0" />
      <geometry>
        <mesh
          filename="package://robot9/meshes/wheel_c_link.STL" />
      </geometry>
    </collision>
  </link>
  <joint
    name="wheel_c_joint"
    type="continuous">
    <origin
      xyz="-0.042 -0.1 0"
      rpy="-3.1416 0 -3.1416" />
    <parent
      link="fork_c_joint" />
    <child
      link="wheel_c_link" />
    <axis
      xyz="0 0 1" />
  </joint>
</robot>